Workbook

Sheet Task Map
A1: Assigned | B1: Project | C1: Stage | D1: Task | E1: Description | F1: Agent | G1: Skill | H1: Document | I1: Integrations | J1: Task Slug | K1: Scope
A2: Owner | B2: Project Type | C2: Stage / Pseudo-stage | D2: Task | E2: Description | F2: Agent | G2: Linked skill | H2: Linked document reference | I2: MCP / app / platform surfaces | J2: Task slug | K2: Project scope
B3: Deal Pipeline | C3: Setup | D3: Project Source Choice | E3: Choose the source of truth or setup route for the project. | F3: =HYPERLINK('Link Config'!$B$2&"plugins/vc/agents/vc-deal-room-setup-guide.md","Deal Pipeline Setup Guide") | G3: None declared | H3: None declared | I3: None declared | J3: project-source-choice | K3: setup
B4: Deal Pipeline | C4: Setup | D4: Project Variable Review | E4: Review workspace and project variables before normal execution. | F4: =HYPERLINK('Link Config'!$B$2&"plugins/vc/agents/vc-deal-room-setup-guide.md","Deal Pipeline Setup Guide") | G4: None declared | H4: None declared | I4: None declared | J4: project-variable-review | K4: setup
B5: Deal Pipeline | C5: Setup | D5: Project Schedule Review | E5: Review optional schedule groups before enabling recurring work. | F5: =HYPERLINK('Link Config'!$B$2&"plugins/vc/agents/vc-deal-room-setup-guide.md","Deal Pipeline Setup Guide") | G5: None declared | H5: None declared | I5: None declared | J5: project-schedule-review | K5: setup
B6: Deal Pipeline | C6: Setup | D6: Project Team Invite Review | E6: Review suggested collaborators before sending invitations. | F6: =HYPERLINK('Link Config'!$B$2&"plugins/vc/agents/vc-deal-room-setup-guide.md","Deal Pipeline Setup Guide") | G6: None declared | H6: None declared | I6: None declared | J6: project-team-invite | K6: setup
A7: Alex | B7: Deal Pipeline | C7: Setup | D7: =HYPERLINK('Link Config'!$B$2&"plugins/vc/tasks/screen-inbound-opportunity.md","Capture Opportunity Intake") | E7: Capture source context, known fields, missing information, and guided project-creation values for one venture-capital opportunity before formal screening. | F7: =HYPERLINK('Link Config'!$B$2&"plugins/vc/agents/vc-dealflow-concierge.md","Dealflow Concierge") | G7: =HYPERLINK('Link Config'!$B$2&"plugins/vc/skills/deal-room-setup-and-source-ingestion/SKILL.md","Deal Pipeline Setup & Source Ingestion") | H7: =HYPERLINK('Link Config'!$B$2&"plugins/vc/alludium/documents/deal-room/deal-room-sop.md","Deal Pipeline Operating SOP (operating_guidance)") | I7: alludium-platform harmonic-mcp-oauth affinity-mcp-server exa-mcp-hosted brave-search-mcp serpapi-mcp firecrawl-mcp-hosted dealroom-mcp google_drive | J7: screen-inbound-opportunity | K7: setup
A8: Alex | B8: Deal Pipeline | C8: Setup | D8: =HYPERLINK('Link Config'!$B$2&"plugins/vc/tasks/screen-inbound-opportunity.md","Capture Opportunity Intake") | E8: Capture source context, known fields, missing information, and guided project-creation values for one venture-capital opportunity before formal screening. | F8: =HYPERLINK('Link Config'!$B$2&"plugins/vc/agents/vc-dealflow-concierge.md","Dealflow Concierge") | G8: =HYPERLINK('Link Config'!$B$2&"plugins/vc/skills/company-research-and-enrichment/SKILL.md","Company Research & Enrichment") | H8: =HYPERLINK('Link Config'!$B$2&"plugins/vc/alludium/documents/shared/evidence-citation-style-guide.md","Evidence And Citation Style Guide (style_guide)") | I8: alludium-platform harmonic-mcp-oauth affinity-mcp-server exa-mcp-hosted brave-search-mcp serpapi-mcp firecrawl-mcp-hosted dealroom-mcp google_drive | J8: screen-inbound-opportunity | K8: setup
A9: Alex | B9: Deal Pipeline | C9: Setup | D9: =HYPERLINK('Link Config'!$B$2&"plugins/vc/tasks/screen-inbound-opportunity.md","Capture Opportunity Intake") | E9: Capture source context, known fields, missing information, and guided project-creation values for one venture-capital opportunity before formal screening. | F9: =HYPERLINK('Link Config'!$B$2&"plugins/vc/agents/vc-dealflow-concierge.md","Dealflow Concierge") | G9: =HYPERLINK('Link Config'!$B$2&"plugins/vc/skills/citation-enforcement/SKILL.md","Citation Enforcement") | H9: =HYPERLINK('Link Config'!$B$2&"plugins/vc/alludium/documents/shared/template-use-guidance.md","Template Use Guidance (operating_guidance)") | I9: alludium-platform harmonic-mcp-oauth affinity-mcp-server exa-mcp-hosted brave-search-mcp serpapi-mcp firecrawl-mcp-hosted dealroom-mcp google_drive | J9: screen-inbound-opportunity | K9: setup
A10: Alex | B10: Deal Pipeline | C10: Setup | D10: =HYPERLINK('Link Config'!$B$2&"plugins/vc/tasks/screen-inbound-opportunity.md","Capture Opportunity Intake") | E10: Capture source context, known fields, missing information, and guided project-creation values for one venture-capital opportunity before formal screening. | F10: =HYPERLINK('Link Config'!$B$2&"plugins/vc/agents/vc-dealflow-concierge.md","Dealflow Concierge") | G10: =HYPERLINK('Link Config'!$B$2&"plugins/vc/skills/pitch-deck-explainer/SKILL.md","Pitch Deck Explainer") | I10: alludium-platform harmonic-mcp-oauth affinity-mcp-server exa-mcp-hosted brave-search-mcp serpapi-mcp firecrawl-mcp-hosted dealroom-mcp google_drive | J10: screen-inbound-opportunity | K10: setup
B11: Deal Pipeline | C11: Setup | D11: Project Source Setup | E11: Review selected source route and setup intent before writes or imports. | F11: =HYPERLINK('Link Config'!$B$2&"plugins/vc/agents/vc-deal-room-setup-guide.md","Deal Pipeline Setup Guide") | G11: None declared | H11: None declared | I11: None declared | J11: project-source-setup | K11: setup
B12: Deal Pipeline | C12: Setup | D12: =HYPERLINK('Link Config'!$B$2&"plugins/vc/tasks/vc-pack-variable-discovery.md","VC Pack Variable Discovery") | E12: Best-effort, review-only discovery for VC Pack Setup variables and invite suggestions. | F12: =HYPERLINK('Link Config'!$B$2&"plugins/vc/agents/vc-deal-room-setup-guide.md","Deal Pipeline Setup Guide") | G12: None declared | H12: None declared | I12: alludium-platform affinity-mcp-server | J12: vc-pack-variable-discovery | K12: setup
B13: Deal Pipeline | C13: Setup | D13: =HYPERLINK('Link Config'!$B$2&"plugins/vc/tasks/affinity-setup.md","Set Up Affinity for Deal Pipelines") | E13: Coordinate Affinity connection readiness, list discovery, read-preview policy, and optional write-back proposal scope for Deal Pipeline setup. | F13: =HYPERLINK('Link Config'!$B$2&"plugins/vc/agents/vc-integration-operator.md","Integration Operator") | G13: =HYPERLINK('Link Config'!$B$2&"plugins/vc/skills/vc-affinity-discovery/SKILL.md","VC Affinity Discovery") | H13: None declared | I13: affinity-mcp-server | J13: affinity-setup | K13: setup
B14: Deal Pipeline | C14: Setup | D14: =HYPERLINK('Link Config'!$B$2&"plugins/vc/tasks/affinity-setup.md","Set Up Affinity for Deal Pipelines") | E14: Coordinate Affinity connection readiness, list discovery, read-preview policy, and optional write-back proposal scope for Deal Pipeline setup. | F14: =HYPERLINK('Link Config'!$B$2&"plugins/vc/agents/vc-integration-operator.md","Integration Operator") | G14: =HYPERLINK('Link Config'!$B$2&"plugins/vc/skills/vc-affinity-sync-read/SKILL.md","VC Affinity Sync Read") | I14: affinity-mcp-server | J14: affinity-setup | K14: setup
B15: Deal Pipeline | C15: Setup | D15: =HYPERLINK('Link Config'!$B$2&"plugins/vc/tasks/affinity-setup.md","Set Up Affinity for Deal Pipelines") | E15: Coordinate Affinity connection readiness, list discovery, read-preview policy, and optional write-back proposal scope for Deal Pipeline setup. | F15: =HYPERLINK('Link Config'!$B$2&"plugins/vc/agents/vc-integration-operator.md","Integration Operator") | G15: =HYPERLINK('Link Config'!$B$2&"plugins/vc/skills/vc-affinity-sync-write/SKILL.md","VC Affinity Sync Write") | I15: affinity-mcp-server | J15: affinity-setup | K15: setup
B16: Deal Pipeline | C16: Setup | D16: =HYPERLINK('Link Config'!$B$2&"plugins/vc/tasks/affinity-setup.md","Set Up Affinity for Deal Pipelines") | E16: Coordinate Affinity connection readiness, list discovery, read-preview policy, and optional write-back proposal scope for Deal Pipeline setup. | F16: =HYPERLINK('Link Config'!$B$2&"plugins/vc/agents/vc-integration-operator.md","Integration Operator") | G16: =HYPERLINK('Link Config'!$B$2&"plugins/vc/skills/citation-enforcement/SKILL.md","Citation Enforcement") | I16: affinity-mcp-server | J16: affinity-setup | K16: setup
B17: Deal Pipeline | C17: Setup | D17: =HYPERLINK('Link Config'!$B$2&"plugins/vc/tasks/affinity-deal-room-import.md","Import Affinity Deal Pipeline Seed") | E17: Import one approved Affinity seed deal into an already-created Deal Pipeline project with source provenance and approval evidence. | F17: =HYPERLINK('Link Config'!$B$2&"plugins/vc/agents/vc-deal-room-setup-guide.md","Deal Pipeline Setup Guide") | G17: =HYPERLINK('Link Config'!$B$2&"plugins/vc/skills/vc-affinity-deal-room-import/SKILL.md","VC Affinity Deal Pipeline Import") | H17: None declared | I17: affinity-mcp-server alludium-platform | J17: affinity-deal-room-import | K17: setup
B18: Deal Pipeline | C18: Setup | D18: =HYPERLINK('Link Config'!$B$2&"plugins/vc/tasks/affinity-deal-room-import.md","Import Affinity Deal Pipeline Seed") | E18: Import one approved Affinity seed deal into an already-created Deal Pipeline project with source provenance and approval evidence. | F18: =HYPERLINK('Link Config'!$B$2&"plugins/vc/agents/vc-deal-room-setup-guide.md","Deal Pipeline Setup Guide") | G18: =HYPERLINK('Link Config'!$B$2&"plugins/vc/skills/vc-affinity-sync-read/SKILL.md","VC Affinity Sync Read") | I18: affinity-mcp-server alludium-platform | J18: affinity-deal-room-import | K18: setup
B19: Deal Pipeline | C19: Setup | D19: =HYPERLINK('Link Config'!$B$2&"plugins/vc/tasks/affinity-deal-room-import.md","Import Affinity Deal Pipeline Seed") | E19: Import one approved Affinity seed deal into an already-created Deal Pipeline project with source provenance and approval evidence. | F19: =HYPERLINK('Link Config'!$B$2&"plugins/vc/agents/vc-deal-room-setup-guide.md","Deal Pipeline Setup Guide") | G19: =HYPERLINK('Link Config'!$B$2&"plugins/vc/skills/deal-room-setup-and-source-ingestion/SKILL.md","Deal Pipeline Setup & Source Ingestion") | I19: affinity-mcp-server alludium-platform | J19: affinity-deal-room-import | K19: setup
B20: Deal Pipeline | C20: Setup | D20: =HYPERLINK('Link Config'!$B$2&"plugins/vc/tasks/affinity-deal-room-import.md","Import Affinity Deal Pipeline Seed") | E20: Import one approved Affinity seed deal into an already-created Deal Pipeline project with source provenance and approval evidence. | F20: =HYPERLINK('Link Config'!$B$2&"plugins/vc/agents/vc-deal-room-setup-guide.md","Deal Pipeline Setup Guide") | G20: =HYPERLINK('Link Config'!$B$2&"plugins/vc/skills/citation-enforcement/SKILL.md","Citation Enforcement") | I20: affinity-mcp-server alludium-platform | J20: affinity-deal-room-import | K20: setup
B21: Deal Pipeline | C21: General | D21: =HYPERLINK('Link Config'!$B$2&"plugins/vc/tasks/prepare-initial-call.md","Prepare Meeting") | E21: Prepare a founder, management, advisor, customer, expert, partner, IC, legal, or closing meeting for one venture-capital opportunity with evidence capture, human review gates, and next-action recommendations. | F21: =HYPERLINK('Link Config'!$B$2&"plugins/vc/agents/vc-meeting-operator.md","Meeting Operator") | G21: =HYPERLINK('Link Config'!$B$2&"plugins/vc/skills/meeting-prep-and-summary/SKILL.md","Meeting Prep & Summary") | H21: =HYPERLINK('Link Config'!$B$2&"plugins/vc/alludium/documents/deal-room/initial-call-brief-template.md","Initial Call Brief Template (output_template, to initial_call_brief_artifact_id)") | I21: alludium-platform harmonic-mcp-oauth affinity-mcp-server exa-mcp-hosted brave-search-mcp serpapi-mcp firecrawl-mcp-hosted dealroom-mcp granola-mcp google_drive | J21: prepare-initial-call | K21: general
B22: Deal Pipeline | C22: General | D22: =HYPERLINK('Link Config'!$B$2&"plugins/vc/tasks/prepare-initial-call.md","Prepare Meeting") | E22: Prepare a founder, management, advisor, customer, expert, partner, IC, legal, or closing meeting for one venture-capital opportunity with evidence capture, human review gates, and next-action recommendations. | F22: =HYPERLINK('Link Config'!$B$2&"plugins/vc/agents/vc-meeting-operator.md","Meeting Operator") | G22: =HYPERLINK('Link Config'!$B$2&"plugins/vc/skills/company-research-and-enrichment/SKILL.md","Company Research & Enrichment") | H22: =HYPERLINK('Link Config'!$B$2&"plugins/vc/alludium/documents/shared/evidence-citation-style-guide.md","Evidence And Citation Style Guide (style_guide)") | I22: alludium-platform harmonic-mcp-oauth affinity-mcp-server exa-mcp-hosted brave-search-mcp serpapi-mcp firecrawl-mcp-hosted dealroom-mcp granola-mcp google_drive | J22: prepare-initial-call | K22: general
B23: Deal Pipeline | C23: General | D23: =HYPERLINK('Link Config'!$B$2&"plugins/vc/tasks/prepare-initial-call.md","Prepare Meeting") | E23: Prepare a founder, management, advisor, customer, expert, partner, IC, legal, or closing meeting for one venture-capital opportunity with evidence capture, human review gates, and next-action recommendations. | F23: =HYPERLINK('Link Config'!$B$2&"plugins/vc/agents/vc-meeting-operator.md","Meeting Operator") | G23: =HYPERLINK('Link Config'!$B$2&"plugins/vc/skills/citation-enforcement/SKILL.md","Citation Enforcement") | H23: =HYPERLINK('Link Config'!$B$2&"plugins/vc/alludium/documents/shared/template-use-guidance.md","Template Use Guidance (operating_guidance)") | I23: alludium-platform harmonic-mcp-oauth affinity-mcp-server exa-mcp-hosted brave-search-mcp serpapi-mcp firecrawl-mcp-hosted dealroom-mcp granola-mcp google_drive | J23: prepare-initial-call | K23: general
B24: Deal Pipeline | C24: General | D24: =HYPERLINK('Link Config'!$B$2&"plugins/vc/tasks/prepare-initial-call.md","Prepare Meeting") | E24: Prepare a founder, management, advisor, customer, expert, partner, IC, legal, or closing meeting for one venture-capital opportunity with evidence capture, human review gates, and next-action recommendations. | F24: =HYPERLINK('Link Config'!$B$2&"plugins/vc/agents/vc-meeting-operator.md","Meeting Operator") | G24: =HYPERLINK('Link Config'!$B$2&"plugins/vc/skills/pitch-deck-explainer/SKILL.md","Pitch Deck Explainer") | I24: alludium-platform harmonic-mcp-oauth affinity-mcp-server exa-mcp-hosted brave-search-mcp serpapi-mcp firecrawl-mcp-hosted dealroom-mcp granola-mcp google_drive | J24: prepare-initial-call | K24: general
A25: Alex | B25: Deal Pipeline | C25: General | D25: =HYPERLINK('Link Config'!$B$2&"plugins/vc/tasks/request-founder-materials.md","Request Founder Materials") | E25: Request Founder Materials for one venture-capital opportunity with evidence capture, human review gates, and next-action recommendations. | F25: =HYPERLINK('Link Config'!$B$2&"plugins/vc/agents/vc-dealflow-concierge.md","Dealflow Concierge") | G25: =HYPERLINK('Link Config'!$B$2&"plugins/vc/skills/citation-enforcement/SKILL.md","Citation Enforcement") | H25: =HYPERLINK('Link Config'!$B$2&"plugins/vc/alludium/documents/deal-room/founder-materials-request-template.md","Founder Materials Request Template (output_template, to founder_materials_request_artifact_id)") | I25: alludium-platform harmonic-mcp-oauth affinity-mcp-server exa-mcp-hosted brave-search-mcp serpapi-mcp firecrawl-mcp-hosted dealroom-mcp google_drive | J25: request-founder-materials | K25: general
A26: Alex | B26: Deal Pipeline | C26: General | D26: =HYPERLINK('Link Config'!$B$2&"plugins/vc/tasks/request-founder-materials.md","Request Founder Materials") | E26: Request Founder Materials for one venture-capital opportunity with evidence capture, human review gates, and next-action recommendations. | F26: =HYPERLINK('Link Config'!$B$2&"plugins/vc/agents/vc-dealflow-concierge.md","Dealflow Concierge") | G26: =HYPERLINK('Link Config'!$B$2&"plugins/vc/skills/founder-materials-request/SKILL.md","Founder Materials Request") | H26: =HYPERLINK('Link Config'!$B$2&"plugins/vc/alludium/documents/shared/file-naming-source-index-sop.md","File Naming And Source Index SOP (operating_guidance)") | I26: alludium-platform harmonic-mcp-oauth affinity-mcp-server exa-mcp-hosted brave-search-mcp serpapi-mcp firecrawl-mcp-hosted dealroom-mcp google_drive | J26: request-founder-materials | K26: general
A27: Alex | B27: Deal Pipeline | C27: General | D27: =HYPERLINK('Link Config'!$B$2&"plugins/vc/tasks/request-founder-materials.md","Request Founder Materials") | E27: Request Founder Materials for one venture-capital opportunity with evidence capture, human review gates, and next-action recommendations. | F27: =HYPERLINK('Link Config'!$B$2&"plugins/vc/agents/vc-dealflow-concierge.md","Dealflow Concierge") | H27: =HYPERLINK('Link Config'!$B$2&"plugins/vc/alludium/documents/shared/template-use-guidance.md","Template Use Guidance (operating_guidance)") | I27: alludium-platform harmonic-mcp-oauth affinity-mcp-server exa-mcp-hosted brave-search-mcp serpapi-mcp firecrawl-mcp-hosted dealroom-mcp google_drive | J27: request-founder-materials | K27: general
A28: Alex | B28: Deal Pipeline | C28: General | D28: =HYPERLINK('Link Config'!$B$2&"plugins/vc/tasks/summarize-initial-call.md","Summarize Meeting Records") | E28: Summarize or ingest meeting records for one venture-capital opportunity with evidence capture, human review gates, and next-action recommendations. | F28: =HYPERLINK('Link Config'!$B$2&"plugins/vc/agents/vc-meeting-operator.md","Meeting Operator") | G28: =HYPERLINK('Link Config'!$B$2&"plugins/vc/skills/meeting-prep-and-summary/SKILL.md","Meeting Prep & Summary") | H28: =HYPERLINK('Link Config'!$B$2&"plugins/vc/alludium/documents/deal-room/customer-insights-summary-template.md","Customer Insights Summary Template (output_template, to customer_insights_artifact_id)") | I28: alludium-platform harmonic-mcp-oauth affinity-mcp-server exa-mcp-hosted brave-search-mcp serpapi-mcp firecrawl-mcp-hosted dealroom-mcp granola-mcp google_drive | J28: summarize-initial-call | K28: general
A29: Alex | B29: Deal Pipeline | C29: General | D29: =HYPERLINK('Link Config'!$B$2&"plugins/vc/tasks/summarize-initial-call.md","Summarize Meeting Records") | E29: Summarize or ingest meeting records for one venture-capital opportunity with evidence capture, human review gates, and next-action recommendations. | F29: =HYPERLINK('Link Config'!$B$2&"plugins/vc/agents/vc-meeting-operator.md","Meeting Operator") | G29: =HYPERLINK('Link Config'!$B$2&"plugins/vc/skills/citation-enforcement/SKILL.md","Citation Enforcement") | H29: =HYPERLINK('Link Config'!$B$2&"plugins/vc/alludium/documents/shared/evidence-citation-style-guide.md","Evidence And Citation Style Guide (style_guide)") | I29: alludium-platform harmonic-mcp-oauth affinity-mcp-server exa-mcp-hosted brave-search-mcp serpapi-mcp firecrawl-mcp-hosted dealroom-mcp granola-mcp google_drive | J29: summarize-initial-call | K29: general
A30: Alex | B30: Deal Pipeline | C30: General | D30: =HYPERLINK('Link Config'!$B$2&"plugins/vc/tasks/summarize-initial-call.md","Summarize Meeting Records") | E30: Summarize or ingest meeting records for one venture-capital opportunity with evidence capture, human review gates, and next-action recommendations. | F30: =HYPERLINK('Link Config'!$B$2&"plugins/vc/agents/vc-meeting-operator.md","Meeting Operator") | G30: =HYPERLINK('Link Config'!$B$2&"plugins/vc/skills/vc-task-and-next-step-generation/SKILL.md","VC Task & Next-Step Generation") | H30: =HYPERLINK('Link Config'!$B$2&"plugins/vc/alludium/documents/shared/template-use-guidance.md","Template Use Guidance (operating_guidance)") | I30: alludium-platform harmonic-mcp-oauth affinity-mcp-server exa-mcp-hosted brave-search-mcp serpapi-mcp firecrawl-mcp-hosted dealroom-mcp granola-mcp google_drive | J30: summarize-initial-call | K30: general
B31: Deal Pipeline | C31: General | D31: =HYPERLINK('Link Config'!$B$2&"plugins/vc/tasks/review-opportunity-status.md","Review Opportunity Status") | E31: Review the current status of one venture-capital opportunity and suggest missing inputs, stage movement, and next tasks without producing a formal investment evaluation document. | F31: =HYPERLINK('Link Config'!$B$2&"plugins/vc/agents/vc-pipeline-autopilot.md","Pipeline Autopilot") | G31: =HYPERLINK('Link Config'!$B$2&"plugins/vc/skills/citation-enforcement/SKILL.md","Citation Enforcement") | H31: =HYPERLINK('Link Config'!$B$2&"plugins/vc/alludium/documents/deal-room/deal-room-sop.md","Deal Pipeline Operating SOP (operating_guidance)") | I31: alludium-platform affinity-mcp-server exa-mcp-hosted brave-search-mcp serpapi-mcp dealroom-mcp | J31: review-opportunity-status | K31: general
B32: Deal Pipeline | C32: General | D32: =HYPERLINK('Link Config'!$B$2&"plugins/vc/tasks/review-opportunity-status.md","Review Opportunity Status") | E32: Review the current status of one venture-capital opportunity and suggest missing inputs, stage movement, and next tasks without producing a formal investment evaluation document. | F32: =HYPERLINK('Link Config'!$B$2&"plugins/vc/agents/vc-pipeline-autopilot.md","Pipeline Autopilot") | G32: =HYPERLINK('Link Config'!$B$2&"plugins/vc/skills/vc-task-and-next-step-generation/SKILL.md","VC Task & Next-Step Generation") | H32: =HYPERLINK('Link Config'!$B$2&"plugins/vc/alludium/documents/shared/opportunity-evaluation-framework.md","Opportunity Evaluation Framework (methodology)") | I32: alludium-platform affinity-mcp-server exa-mcp-hosted brave-search-mcp serpapi-mcp dealroom-mcp | J32: review-opportunity-status | K32: general
B33: Deal Pipeline | C33: General | D33: =HYPERLINK('Link Config'!$B$2&"plugins/vc/tasks/review-opportunity-status.md","Review Opportunity Status") | E33: Review the current status of one venture-capital opportunity and suggest missing inputs, stage movement, and next tasks without producing a formal investment evaluation document. | F33: =HYPERLINK('Link Config'!$B$2&"plugins/vc/agents/vc-pipeline-autopilot.md","Pipeline Autopilot") | H33: =HYPERLINK('Link Config'!$B$2&"plugins/vc/alludium/documents/shared/evaluation-workstream-guide.md","Evaluation Workstream Guide (methodology)") | I33: alludium-platform affinity-mcp-server exa-mcp-hosted brave-search-mcp serpapi-mcp dealroom-mcp | J33: review-opportunity-status | K33: general
B34: Deal Pipeline | C34: General | D34: =HYPERLINK('Link Config'!$B$2&"plugins/vc/tasks/review-opportunity-status.md","Review Opportunity Status") | E34: Review the current status of one venture-capital opportunity and suggest missing inputs, stage movement, and next tasks without producing a formal investment evaluation document. | F34: =HYPERLINK('Link Config'!$B$2&"plugins/vc/agents/vc-pipeline-autopilot.md","Pipeline Autopilot") | H34: =HYPERLINK('Link Config'!$B$2&"plugins/vc/alludium/documents/shared/evidence-citation-style-guide.md","Evidence And Citation Style Guide (style_guide)") | I34: alludium-platform affinity-mcp-server exa-mcp-hosted brave-search-mcp serpapi-mcp dealroom-mcp | J34: review-opportunity-status | K34: general
B35: Deal Pipeline | C35: General | D35: =HYPERLINK('Link Config'!$B$2&"plugins/vc/tasks/review-opportunity-status.md","Review Opportunity Status") | E35: Review the current status of one venture-capital opportunity and suggest missing inputs, stage movement, and next tasks without producing a formal investment evaluation document. | F35: =HYPERLINK('Link Config'!$B$2&"plugins/vc/agents/vc-pipeline-autopilot.md","Pipeline Autopilot") | H35: =HYPERLINK('Link Config'!$B$2&"plugins/vc/alludium/documents/shared/template-use-guidance.md","Template Use Guidance (operating_guidance)") | I35: alludium-platform affinity-mcp-server exa-mcp-hosted brave-search-mcp serpapi-mcp dealroom-mcp | J35: review-opportunity-status | K35: general
B36: Deal Pipeline | C36: Integration Support | D36: =HYPERLINK('Link Config'!$B$2&"plugins/vc/tasks/affinity-sync-read.md","Preview Affinity Pipeline Import") | E36: Preview selected Affinity opportunity, company, person, note, and list-entry data before importing it into Deal Pipeline context. | F36: =HYPERLINK('Link Config'!$B$2&"plugins/vc/agents/vc-integration-operator.md","Integration Operator") | G36: =HYPERLINK('Link Config'!$B$2&"plugins/vc/skills/vc-affinity-sync-read/SKILL.md","VC Affinity Sync Read") | H36: None declared | I36: None declared | J36: affinity-sync-read | K36: project_management
B37: Deal Pipeline | C37: Integration Support | D37: =HYPERLINK('Link Config'!$B$2&"plugins/vc/tasks/affinity-sync-read.md","Preview Affinity Pipeline Import") | E37: Preview selected Affinity opportunity, company, person, note, and list-entry data before importing it into Deal Pipeline context. | F37: =HYPERLINK('Link Config'!$B$2&"plugins/vc/agents/vc-integration-operator.md","Integration Operator") | G37: =HYPERLINK('Link Config'!$B$2&"plugins/vc/skills/citation-enforcement/SKILL.md","Citation Enforcement") | I37: None declared | J37: affinity-sync-read | K37: project_management
B38: Deal Pipeline | C38: Integration Support | D38: =HYPERLINK('Link Config'!$B$2&"plugins/vc/tasks/affinity-sync-write.md","Draft Affinity Write-Back Proposals") | E38: Draft reviewable Affinity note, field, and stage update proposals from VC task outputs. | F38: =HYPERLINK('Link Config'!$B$2&"plugins/vc/agents/vc-integration-operator.md","Integration Operator") | G38: =HYPERLINK('Link Config'!$B$2&"plugins/vc/skills/vc-affinity-sync-write/SKILL.md","VC Affinity Sync Write") | H38: None declared | I38: None declared | J38: affinity-sync-write | K38: project_management
B39: Deal Pipeline | C39: Integration Support | D39: =HYPERLINK('Link Config'!$B$2&"plugins/vc/tasks/affinity-sync-write.md","Draft Affinity Write-Back Proposals") | E39: Draft reviewable Affinity note, field, and stage update proposals from VC task outputs. | F39: =HYPERLINK('Link Config'!$B$2&"plugins/vc/agents/vc-integration-operator.md","Integration Operator") | G39: =HYPERLINK('Link Config'!$B$2&"plugins/vc/skills/citation-enforcement/SKILL.md","Citation Enforcement") | I39: None declared | J39: affinity-sync-write | K39: project_management
B40: Deal Pipeline | C40: Integration Support | D40: =HYPERLINK('Link Config'!$B$2&"plugins/vc/tasks/google-drive-sync-write.md","Draft Google Drive File Proposals") | E40: Draft reviewable Google Drive file or comment proposals from VC task outputs without performing broad Drive mutations. | F40: =HYPERLINK('Link Config'!$B$2&"plugins/vc/agents/vc-integration-operator.md","Integration Operator") | G40: =HYPERLINK('Link Config'!$B$2&"plugins/vc/skills/vc-google-drive-sync-write/SKILL.md","VC Google Drive Sync Write") | H40: None declared | I40: None declared | J40: google-drive-sync-write | K40: project_management
...

Sheet Skill Map
A1: Assigned | B1: Skill | C1: Agent Usage Count | D1: All Task Usage Count | E1: Project Task Usage Count | F1: Setup / Management Task Usage Count | G1: Agents | H1: Project Tasks
A2: Owner | B2: Linked skill | C2: Agents using skill | D2: All task rows | E2: Project-instance task rows | F2: Setup/general/management task rows | G2: Agents | H2: Tasks
B3: =HYPERLINK('Link Config'!$B$2&"plugins/vc/skills/citation-enforcement/SKILL.md","Citation Enforcement") | C3: 12 | D3: 90 | E3: 54 | F3: 36 | G3: Deal Pipeline Setup Guide Dealflow Concierge Diligence Analyst Evaluation Analyst First Look Analyst IC Prep Producer Integration Operator Legal & Compliance Desk Meeting Operator Origination Scout Pipeline Autopilot Sourcing Operator | H3: Analyze Deal Terms Audit LinkedIn Query Spend Capture Investment Management Handoff Capture Opportunity Intake Check Affinity Relationship Context Configure Companies House Public Register Preview Configure Origination Pipeline Coordinate Capital Call And Completion Create IC Memo Discover Companies House Candidates Discover GitHub Builder Signals Discover LinkedIn Founder Candidates Discover Reddit Builder Signals Discover X Founder Signals Draft Affinity Write-Back Proposals Draft Google Drive File Proposals Draft Notion Update Proposals Draft Slack Handoff Notifications Enrich Sourcing Candidate Explore Affinity Lists and Stages Explore Apify Origination Sources Explore Companies House Public Register Scope Explore Google Drive Sources Explore Harmonic Source Scopes Explore Notion Pages and Databases Explore Slack Channels for VC Context Generate Diligence Questions Generate Sourcing Digest Import Affinity Deal Pipeline Seed Ingest Manual Sourcing Tip Manage Closing Checklist Prepare Deal Flow Agenda Prepare IC Agenda Prepare Initial LinkedIn Reachout Prepare Lead Gen Packet Prepare Meeting Prepare Outreach Draft Queue Prepare Partner Review Pack Prepare Portfolio Onboarding Prepare Prospect Summary Prepare Second Reachout Email Prepare Team Review Pack Preview Affinity Pipeline Import Preview Apify Origination Results Preview Companies House Public Register Results Preview Google Drive Context Preview Harmonic Search Results Preview Notion Context Preview Slack Deal Context Promote Candidate to Deal Pipeline Record IC Decision Record LinkedIn Connection Attempt Request Founder Materials Review IC Memo Review Investment Documents Review Opportunity Status Review Outreach Outcome Review Portfolio Overlap Review Reddit Candidate Inbox Review Source Errors and Spend Review Term Sheet Review Unicorn Signature Run Commercial DD Run Commercial Evaluation Run Deal Fit Analysis Run Financial DD Run Financial Evaluation Run Founder Evaluation Run Investment Fit Screen Run Legal Diligence Run Opportunity Evaluation Run Team Evaluation Run Technical DD Run Technical Evaluation Run VC Sourcing Pipeline Score Sourcing Candidate Screen Active Sourcing Candidate Screen Founder-Connected Candidate Screen Identified Candidate Set Up Affinity for Deal Pipelines Set Up Apify for Origination Set Up Google Drive for Deal Pipelines Set Up Harmonic for Deal Pipelines Set Up Notion for Deal Pipelines Set Up Slack for Deal Pipelines Source Thesis Targets Summarize Meeting Records Sync Sourcing Candidate Track Term Sheet Negotiation Verify Conditions Precedent
B4: =HYPERLINK('Link Config'!$B$2&"plugins/vc/skills/vc-source-registry-and-state-management/SKILL.md","VC Source Registry & State Management") | C4: 1 | D4: 9 | E4: 8 | F4: 1 | G4: Sourcing Operator | H4: Audit LinkedIn Query Spend Discover Companies House Candidates Discover GitHub Builder Signals Discover LinkedIn Founder Candidates Discover Reddit Builder Signals Discover X Founder Signals Review Source Errors and Spend Run VC Sourcing Pipeline Sync Sourcing Candidate
B5: =HYPERLINK('Link Config'!$B$2&"plugins/vc/skills/red-flags-scanner/SKILL.md","Red Flags Scanner") | C5: 5 | D5: 8 | E5: 8 | F5: 0 | G5: Dealflow Concierge Diligence Analyst Evaluation Analyst First Look Analyst Legal & Compliance Desk | H5: Review Term Sheet Run Founder Evaluation Run Investment Fit Screen Run Legal Diligence Run Opportunity Evaluation Run Team Evaluation Run Technical DD Run Technical Evaluation
B6: =HYPERLINK('Link Config'!$B$2&"plugins/vc/skills/vc-task-and-next-step-generation/SKILL.md","VC Task & Next-Step Generation") | C6: 4 | D6: 7 | E6: 3 | F6: 4 | G6: IC Prep Producer Legal & Compliance Desk Meeting Operator Pipeline Autopilot | H6: Capture Investment Management Handoff Coordinate Capital Call And Completion Manage Closing Checklist Prepare Deal Flow Agenda Record IC Decision Review Opportunity Status Summarize Meeting Records
B7: =HYPERLINK('Link Config'!$B$2&"plugins/vc/skills/vc-outreach-draft-queue/SKILL.md","VC Outreach Draft Queue") | C7: 1 | D7: 6 | E7: 6 | F7: 0 | G7: Sourcing Operator | H7: Prepare Initial LinkedIn Reachout Prepare Outreach Draft Queue Prepare Second Reachout Email Record LinkedIn Connection Attempt Review Outreach Outcome Screen Founder-Connected Candidate
B8: =HYPERLINK('Link Config'!$B$2&"plugins/vc/skills/vc-sourcing-dedupe-and-novelty-check/SKILL.md","VC Sourcing Dedupe & Novelty Check") | C8: 1 | D8: 6 | E8: 6 | F8: 0 | G8: Sourcing Operator | H8: Enrich Sourcing Candidate Ingest Manual Sourcing Tip Review Reddit Candidate Inbox Score Sourcing Candidate Screen Identified Candidate Sync Sourcing Candidate
B9: =HYPERLINK('Link Config'!$B$2&"plugins/vc/skills/vc-sourcing-verdict-and-screening/SKILL.md","VC Sourcing Verdict & Screening") | C9: 1 | D9: 6 | E9: 6 | F9: 0 | G9: Sourcing Operator | H9: Review Unicorn Signature Run Deal Fit Analysis Score Sourcing Candidate Screen Active Sourcing Candidate Screen Founder-Connected Candidate Screen Identified Candidate
B10: =HYPERLINK('Link Config'!$B$2&"plugins/vc/skills/closing-coordination-and-cp-tracking/SKILL.md","Closing Coordination & CP Tracking") | C10: 1 | D10: 5 | E10: 5 | F10: 0 | G10: Legal & Compliance Desk | H10: Coordinate Capital Call And Completion Manage Closing Checklist Review Investment Documents Review Term Sheet Verify Conditions Precedent
B11: =HYPERLINK('Link Config'!$B$2&"plugins/vc/skills/founder-outreach-and-intro-paths/SKILL.md","Founder Outreach & Intro Paths") | C11: 2 | D11: 5 | E11: 5 | F11: 0 | G11: Origination Scout Sourcing Operator | H11: Prepare Initial LinkedIn Reachout Prepare Outreach Draft Queue Prepare Second Reachout Email Record LinkedIn Connection Attempt Source Thesis Targets
B12: =HYPERLINK('Link Config'!$B$2&"plugins/vc/skills/company-research-and-enrichment/SKILL.md","Company Research & Enrichment") | C12: 8 | D12: 4 | E12: 1 | F12: 3 | G12: Dealflow Concierge Diligence Analyst Evaluation Analyst First Look Analyst Meeting Operator Origination Scout Pipeline Autopilot Sourcing Operator | H12: Capture Opportunity Intake Prepare Lead Gen Packet Prepare Meeting Source Thesis Targets
B13: =HYPERLINK('Link Config'!$B$2&"plugins/vc/skills/ic-memo-assembly/SKILL.md","IC Memo Assembly") | C13: 2 | D13: 4 | E13: 4 | F13: 0 | G13: Diligence Analyst IC Prep Producer | H13: Create IC Memo Prepare Partner Review Pack Prepare Team Review Pack Review IC Memo
B14: =HYPERLINK('Link Config'!$B$2&"plugins/vc/skills/ic-risk-checklist-and-decision-log/SKILL.md","IC Risk Checklist & Decision Log") | C14: 1 | D14: 4 | E14: 4 | F14: 0 | G14: IC Prep Producer | H14: Create IC Memo Prepare IC Agenda Record IC Decision Review IC Memo
B15: =HYPERLINK('Link Config'!$B$2&"plugins/vc/skills/investment-screening-framework/SKILL.md","Investment Screening Framework") | C15: 5 | D15: 4 | E15: 4 | F15: 0 | G15: Dealflow Concierge First Look Analyst Meeting Operator Origination Scout Sourcing Operator | H15: Run Deal Fit Analysis Run Investment Fit Screen Screen Active Sourcing Candidate Screen Founder-Connected Candidate
B16: =HYPERLINK('Link Config'!$B$2&"plugins/vc/skills/deal-room-setup-and-source-ingestion/SKILL.md","Deal Pipeline Setup & Source Ingestion") | C16: 3 | D16: 3 | E16: 1 | F16: 2 | G16: Deal Pipeline Setup Guide Dealflow Concierge Sourcing Operator | H16: Capture Opportunity Intake Import Affinity Deal Pipeline Seed Promote Candidate to Deal Pipeline
B17: =HYPERLINK('Link Config'!$B$2&"plugins/vc/skills/meeting-prep-and-summary/SKILL.md","Meeting Prep & Summary") | C17: 2 | D17: 3 | E17: 1 | F17: 2 | G17: IC Prep Producer Meeting Operator | H17: Prepare IC Agenda Prepare Meeting Summarize Meeting Records
B18: =HYPERLINK('Link Config'!$B$2&"plugins/vc/skills/vc-affinity-sync-read/SKILL.md","VC Affinity Sync Read") | C18: 2 | D18: 3 | E18: 0 | F18: 3 | G18: Deal Pipeline Setup Guide Integration Operator | H18: Import Affinity Deal Pipeline Seed Preview Affinity Pipeline Import Set Up Affinity for Deal Pipelines
B19: =HYPERLINK('Link Config'!$B$2&"plugins/vc/skills/vc-companies-house-sourcing/SKILL.md","VC Companies House Sourcing") | C19: 2 | D19: 3 | E19: 1 | F19: 2 | G19: Integration Operator Sourcing Operator | H19: Configure Companies House Public Register Preview Discover Companies House Candidates Explore Companies House Public Register Scope
B20: =HYPERLINK('Link Config'!$B$2&"plugins/vc/skills/vc-notion-sync-write/SKILL.md","VC Notion Sync Write") | C20: 2 | D20: 3 | E20: 1 | F20: 2 | G20: Integration Operator Sourcing Operator | H20: Draft Notion Update Proposals Set Up Notion for Deal Pipelines Sync Sourcing Candidate
B21: =HYPERLINK('Link Config'!$B$2&"plugins/vc/skills/deal-terms-analysis/SKILL.md","Deal Terms Analysis") | C21: 1 | D21: 2 | E21: 2 | F21: 0 | G21: Legal & Compliance Desk | H21: Analyze Deal Terms Track Term Sheet Negotiation
B22: =HYPERLINK('Link Config'!$B$2&"plugins/vc/skills/investment-diligence-question-framework/SKILL.md","Investment Diligence Question Framework") | C22: 2 | D22: 2 | E22: 2 | F22: 0 | G22: Diligence Analyst Evaluation Analyst | H22: Generate Diligence Questions Run Opportunity Evaluation
B23: =HYPERLINK('Link Config'!$B$2&"plugins/vc/skills/legal-diligence-coordination/SKILL.md","Legal Diligence Coordination") | C23: 1 | D23: 2 | E23: 2 | F23: 0 | G23: Legal & Compliance Desk | H23: Review Investment Documents Run Legal Diligence
B24: =HYPERLINK('Link Config'!$B$2&"plugins/vc/skills/pitch-deck-explainer/SKILL.md","Pitch Deck Explainer") | C24: 2 | D24: 2 | E24: 0 | F24: 2 | G24: Dealflow Concierge Meeting Operator | H24: Capture Opportunity Intake Prepare Meeting
B25: =HYPERLINK('Link Config'!$B$2&"plugins/vc/skills/team-and-hiring-assessment/SKILL.md","Team & Hiring Assessment") | C25: 1 | D25: 2 | E25: 2 | F25: 0 | G25: Diligence Analyst | H25: Run Founder Evaluation Run Technical DD
B26: =HYPERLINK('Link Config'!$B$2&"plugins/vc/skills/vc-affinity-discovery/SKILL.md","VC Affinity Discovery") | C26: 2 | D26: 2 | E26: 0 | F26: 2 | G26: Deal Pipeline Setup Guide Integration Operator | H26: Explore Affinity Lists and Stages Set Up Affinity for Deal Pipelines
B27: =HYPERLINK('Link Config'!$B$2&"plugins/vc/skills/vc-affinity-sync-write/SKILL.md","VC Affinity Sync Write") | C27: 2 | D27: 2 | E27: 0 | F27: 2 | G27: Deal Pipeline Setup Guide Integration Operator | H27: Draft Affinity Write-Back Proposals Set Up Affinity for Deal Pipelines
B28: =HYPERLINK('Link Config'!$B$2&"plugins/vc/skills/vc-apify-discovery/SKILL.md","VC Apify Discovery") | C28: 1 | D28: 2 | E28: 0 | F28: 2 | G28: Integration Operator | H28: Explore Apify Origination Sources Set Up Apify for Origination
B29: =HYPERLINK('Link Config'!$B$2&"plugins/vc/skills/vc-apify-sync-read/SKILL.md","VC Apify Sync Read") | C29: 1 | D29: 2 | E29: 0 | F29: 2 | G29: Integration Operator | H29: Preview Apify Origination Results Set Up Apify for Origination
B30: =HYPERLINK('Link Config'!$B$2&"plugins/vc/skills/vc-companies-house-sync-read/SKILL.md","VC Companies House Sync Read") | C30: 1 | D30: 2 | E30: 0 | F30: 2 | G30: Integration Operator | H30: Configure Companies House Public Register Preview Preview Companies House Public Register Results
B31: =HYPERLINK('Link Config'!$B$2&"plugins/vc/skills/vc-google-drive-discovery/SKILL.md","VC Google Drive Discovery") | C31: 1 | D31: 2 | E31: 0 | F31: 2 | G31: Integration Operator | H31: Explore Google Drive Sources Set Up Google Drive for Deal Pipelines
B32: =HYPERLINK('Link Config'!$B$2&"plugins/vc/skills/vc-google-drive-sync-read/SKILL.md","VC Google Drive Sync Read") | C32: 1 | D32: 2 | E32: 0 | F32: 2 | G32: Integration Operator | H32: Preview Google Drive Context Set Up Google Drive for Deal Pipelines
B33: =HYPERLINK('Link Config'!$B$2&"plugins/vc/skills/vc-google-drive-sync-write/SKILL.md","VC Google Drive Sync Write") | C33: 1 | D33: 2 | E33: 0 | F33: 2 | G33: Integration Operator | H33: Draft Google Drive File Proposals Set Up Google Drive for Deal Pipelines
B34: =HYPERLINK('Link Config'!$B$2&"plugins/vc/skills/vc-harmonic-discovery/SKILL.md","VC Harmonic Discovery") | C34: 1 | D34: 2 | E34: 0 | F34: 2 | G34: Integration Operator | H34: Explore Harmonic Source Scopes Set Up Harmonic for Deal Pipelines
B35: =HYPERLINK('Link Config'!$B$2&"plugins/vc/skills/vc-harmonic-sync-read/SKILL.md","VC Harmonic Sync Read") | C35: 1 | D35: 2 | E35: 0 | F35: 2 | G35: Integration Operator | H35: Preview Harmonic Search Results Set Up Harmonic for Deal Pipelines
B36: =HYPERLINK('Link Config'!$B$2&"plugins/vc/skills/vc-notion-discovery/SKILL.md","VC Notion Discovery") | C36: 1 | D36: 2 | E36: 0 | F36: 2 | G36: Integration Operator | H36: Explore Notion Pages and Databases Set Up Notion for Deal Pipelines
B37: =HYPERLINK('Link Config'!$B$2&"plugins/vc/skills/vc-notion-sync-read/SKILL.md","VC Notion Sync Read") | C37: 1 | D37: 2 | E37: 0 | F37: 2 | G37: Integration Operator | H37: Preview Notion Context Set Up Notion for Deal Pipelines
B38: =HYPERLINK('Link Config'!$B$2&"plugins/vc/skills/vc-origination-deal-room-promotion/SKILL.md","Origination Deal Pipeline Promotion") | C38: 1 | D38: 2 | E38: 2 | F38: 0 | G38: Sourcing Operator | H38: Promote Candidate to Deal Pipeline Review Outreach Outcome
B39: =HYPERLINK('Link Config'!$B$2&"plugins/vc/skills/vc-origination-ic-summary-preparation/SKILL.md","Origination Prospect Summary Preparation") | C39: 1 | D39: 2 | E39: 2 | F39: 0 | G39: Sourcing Operator | H39: Prepare Prospect Summary Review Unicorn Signature
B40: =HYPERLINK('Link Config'!$B$2&"plugins/vc/skills/vc-origination-pipeline-orchestration/SKILL.md","Origination Pipeline Orchestration") | C40: 1 | D40: 2 | E40: 1 | F40: 1 | G40: Sourcing Operator | H40: Configure Origination Pipeline Run VC Sourcing Pipeline
...

Sheet Document Catalog
A1: Document | B1: Type | C1: Projects | D1: Description | E1: Related Tasks
A2: Linked document | B2: Document Type | C2: Supported Project Types | D2: Description | E2: Related Task Slugs
A3: =HYPERLINK('Link Config'!$B$2&"plugins/vc/alludium/documents/shared/investment-screening-framework.md","Investment Screening Framework") | B3: methodology | C3: vc_deal_room vc_origination_pipeline | D3: Reusable first-look scorecard methodology for deciding whether a venture opportunity deserves deeper work. | E3: run-investment-screen score-sourcing-candidates screen-active-sourcing-candidates screen-inbound-opportunity
A4: =HYPERLINK('Link Config'!$B$2&"plugins/vc/alludium/documents/shared/investment-diligence-question-framework.md","Investment Diligence Question Framework") | B4: methodology | C4: vc_deal_room vc_origination_pipeline vc_investment_management | D4: Structured diligence question-bank methodology for converting knowns, unknowns, and risks into workstream questions. | E4: generate-diligence-questions run-commercial-dd run-financial-dd run-technical-dd
A5: =HYPERLINK('Link Config'!$B$2&"plugins/vc/alludium/documents/shared/opportunity-evaluation-framework.md","Opportunity Evaluation Framework") | B5: methodology | C5: vc_deal_room | D5: Evidence-led post-screening opportunity evaluation methodology with scoring, thesis tension, gating risk, and meeting/data-room planning standards. | E5: create-ic-memo generate-diligence-questions prepare-partner-review-pack prepare-team-review-pack review-opportunity-status review-ic-memo run-follow-up-evaluation run-team-evaluation run-financial-evaluation run-technical-evaluation run-commercial-evaluation
A6: =HYPERLINK('Link Config'!$B$2&"plugins/vc/alludium/documents/shared/evaluation-workstream-guide.md","Evaluation Workstream Guide") | B6: methodology | C6: vc_deal_room | D6: Lightweight commercial, technical, financial, and team evaluation guidance for post-screening work before formal diligence. | E6: create-ic-memo generate-diligence-questions prepare-partner-review-pack prepare-team-review-pack review-ic-memo review-opportunity-status run-follow-up-evaluation run-team-evaluation run-financial-evaluation run-technical-evaluation run-commercial-evaluation
A7: =HYPERLINK('Link Config'!$B$2&"plugins/vc/alludium/documents/deal-room/commercial-evaluation-guide.md","Commercial Evaluation Guide") | B7: methodology | C7: vc_deal_room | D7: Lightweight commercial evaluation guidance for market, customer, GTM, pricing, and competition hypotheses. | E7: generate-diligence-questions run-follow-up-evaluation run-commercial-evaluation
A8: =HYPERLINK('Link Config'!$B$2&"plugins/vc/alludium/documents/deal-room/technical-evaluation-guide.md","Technical Evaluation Guide") | B8: methodology | C8: vc_deal_room | D8: Lightweight technical evaluation guidance for product, architecture, technical edge, IP, data, and roadmap hypotheses. | E8: generate-diligence-questions run-follow-up-evaluation run-technical-evaluation
A9: =HYPERLINK('Link Config'!$B$2&"plugins/vc/alludium/documents/deal-room/financial-evaluation-guide.md","Financial Evaluation Guide") | B9: methodology | C9: vc_deal_room | D9: Lightweight financial evaluation guidance for forecast plausibility, burn, runway, use of funds, valuation, ownership, and financing risk. | E9: generate-diligence-questions run-follow-up-evaluation run-financial-evaluation
A10: =HYPERLINK('Link Config'!$B$2&"plugins/vc/alludium/documents/shared/evidence-citation-style-guide.md","Evidence And Citation Style Guide") | B10: style_guide | C10: vc_deal_room vc_origination_pipeline vc_investment_management | D10: Pack-level style guide for citations, assumptions, source confidence, and claim hygiene across VC documents. | E10: create-ic-memo generate-diligence-questions prepare-partner-review-pack prepare-sourcing-ic-summary prepare-team-review-pack record-ic-decision run-commercial-dd run-financial-dd run-founder-evaluation run-investment-screen run-sourcing-pipeline run-technical-dd screen-inbound-opportunity run-commercial-evaluation run-technical-evaluation run-financial-evaluation run-team-evaluation
A11: =HYPERLINK('Link Config'!$B$2&"plugins/vc/alludium/documents/shared/template-use-guidance.md","Template Use Guidance") | B11: sop | C11: vc_deal_room vc_origination_pipeline vc_investment_management | D11: Operating guidance for applying VC document templates as adaptable scaffolds without producing generic filler. | E11: audit-linkedin-query-spend configure-origination-pipeline create-ic-memo generate-diligence-questions generate-sourcing-digest manage-closing-checklist prepare-ic-agenda prepare-initial-call prepare-lead-gen-packet prepare-outreach-draft-queue prepare-partner-review-pack prepare-portfolio-onboarding prepare-sourcing-ic-summary prepare-team-review-pack promote-candidate-to-deal-room record-ic-decision request-founder-materials review-ic-memo review-source-errors-and-spend review-term-sheet run-commercial-dd run-financial-dd run-follow-up-evaluation run-team-evaluation run-financial-evaluation run-technical-evaluation run-commercial-evaluation run-founder-evaluation run-investment-screen run-sourcing-pipeline run-technical-dd score-sourcing-candidates screen-active-sourcing-candidates screen-inbound-opportunity source-thesis-targets summarize-initial-call verify-conditions-precedent
A12: =HYPERLINK('Link Config'!$B$2&"plugins/vc/alludium/documents/shared/file-naming-source-index-sop.md","File Naming And Source Index SOP") | B12: sop | C12: vc_deal_room vc_origination_pipeline vc_investment_management | D12: Operating convention for naming files, tracking source provenance, and maintaining a compact source index. | E12: request-founder-materials run-sourcing-pipeline sync-sourcing-candidates
A13: =HYPERLINK('Link Config'!$B$2&"plugins/vc/alludium/documents/deal-room/deal-room-sop.md","Deal Pipeline Operating SOP") | B13: sop | C13: vc_deal_room | D13: End-to-end Deal Pipeline operating method from intake through closing and portfolio handoff. | E13: prepare-partner-review-pack prepare-team-review-pack review-opportunity-status
A14: =HYPERLINK('Link Config'!$B$2&"plugins/vc/alludium/documents/deal-room/founder-materials-request-template.md","Founder Materials Request Template") | B14: template | C14: vc_deal_room | D14: Reusable founder request template for source materials, financials, customer evidence, technical context, and legal basics. | E14: request-founder-materials
A15: =HYPERLINK('Link Config'!$B$2&"plugins/vc/alludium/documents/deal-room/thesis-target-list-template.md","Thesis Target List Template") | B15: template | C15: vc_origination_pipeline | D15: Reusable target-list format for thesis-led sourcing and warm-intro planning. | E15: source-thesis-targets
A16: =HYPERLINK('Link Config'!$B$2&"plugins/vc/alludium/documents/deal-room/lead-generation-packet-template.md","Lead Generation Packet Template") | B16: template | C16: vc_origination_pipeline | D16: Reusable management-level packet for thesis-led lead generation reviews. | E16: prepare-lead-gen-packet
A17: =HYPERLINK('Link Config'!$B$2&"plugins/vc/alludium/documents/deal-room/initial-call-brief-template.md","Initial Call Brief Template") | B17: template | C17: vc_deal_room | D17: Reusable pre-call brief for first founder or management meetings. | E17: prepare-initial-call
A18: =HYPERLINK('Link Config'!$B$2&"plugins/vc/alludium/documents/deal-room/customer-insights-summary-template.md","Customer Insights Summary Template") | B18: template | C18: vc_deal_room | D18: Reusable meeting-record summary for customer, founder, and diligence call evidence. | E18: summarize-initial-call
A19: =HYPERLINK('Link Config'!$B$2&"plugins/vc/alludium/documents/deal-room/follow-up-evaluation-template.md","Opportunity Evaluation Template") | B19: template | C19: vc_deal_room | D19: Reusable deeper opportunity evaluation after investment screening and early evidence collection. | E19: run-follow-up-evaluation
A20: =HYPERLINK('Link Config'!$B$2&"plugins/vc/alludium/documents/deal-room/team-evaluation-template.md","Team Evaluation Template") | B20: template | C20: vc_deal_room | D20: Output template for lightweight team and founder evaluation before formal diligence. | E20: run-team-evaluation
A21: =HYPERLINK('Link Config'!$B$2&"plugins/vc/alludium/documents/deal-room/financial-evaluation-template.md","Financial Evaluation Template") | B21: template | C21: vc_deal_room | D21: Output template for lightweight financial and financing evaluation before formal diligence. | E21: run-financial-evaluation
A22: =HYPERLINK('Link Config'!$B$2&"plugins/vc/alludium/documents/deal-room/technical-evaluation-template.md","Technical Evaluation Template") | B22: template | C22: vc_deal_room | D22: Output template for lightweight technical and product evaluation before formal diligence. | E22: run-technical-evaluation
A23: =HYPERLINK('Link Config'!$B$2&"plugins/vc/alludium/documents/deal-room/commercial-evaluation-template.md","Commercial Evaluation Template") | B23: template | C23: vc_deal_room | D23: Output template for lightweight commercial evaluation before formal diligence. | E23: run-commercial-evaluation
A24: =HYPERLINK('Link Config'!$B$2&"plugins/vc/alludium/documents/deal-room/investment-memo-template.md","Investment Memo Template") | B24: template | C24: vc_deal_room | D24: Reusable IC investment memo structure with thesis, evidence, risks, valuation, diligence, and decision ask. | E24: create-ic-memo review-ic-memo
A25: =HYPERLINK('Link Config'!$B$2&"plugins/vc/alludium/documents/deal-room/ic-agenda-template.md","IC Agenda Template") | B25: template | C25: vc_deal_room | D25: Reusable investment committee agenda for sequencing discussion, open questions, decision items, and pre-reads. | E25: prepare-ic-agenda
A26: =HYPERLINK('Link Config'!$B$2&"plugins/vc/alludium/documents/deal-room/ic-decision-record-template.md","IC Decision Record Template") | B26: template | C26: vc_deal_room | D26: Reusable decision record for approvals, conditions, dissent, follow-ups, and evidence references. | E26: record-ic-decision
A27: =HYPERLINK('Link Config'!$B$2&"plugins/vc/alludium/documents/deal-room/diligence-report-template.md","Diligence Report Template") | B27: template | C27: vc_investment_management | D27: Reusable diligence report structure for commercial, technical, financial, founder, and legal workstreams. | E27: run-commercial-dd run-financial-dd run-founder-evaluation run-technical-dd
A28: =HYPERLINK('Link Config'!$B$2&"plugins/vc/alludium/documents/deal-room/formal-diligence-workstream-guide.md","Formal Diligence Workstream Guide") | B28: methodology | C28: vc_deal_room vc_investment_management | D28: Verification-oriented diligence workstream methodology for commercial, financial, technical, founder/team, legal, market, terms, and exit review. | E28: create-ic-memo generate-diligence-questions prepare-partner-review-pack prepare-team-review-pack review-ic-memo run-commercial-dd run-financial-dd run-founder-evaluation run-legal-diligence run-technical-dd
A29: =HYPERLINK('Link Config'!$B$2&"plugins/vc/alludium/documents/deal-room/formal-diligence-checklist.md","Formal Diligence Checklist") | B29: checklist | C29: vc_deal_room vc_investment_management | D29: Full formal diligence checklist covering leadership, technical, commercial, market, financial, legal, deal-terms, exit, and company-structure workstreams. | E29: create-ic-memo generate-diligence-questions prepare-partner-review-pack prepare-team-review-pack review-ic-memo run-commercial-dd run-financial-dd run-founder-evaluation run-legal-diligence run-technical-dd
A30: =HYPERLINK('Link Config'!$B$2&"plugins/vc/alludium/documents/deal-room/review-pack-checklist.md","Review Pack Checklist") | B30: checklist | C30: vc_deal_room | D30: Checklist for team review and partner review packs before escalation to IC materials. | E30: prepare-partner-review-pack prepare-team-review-pack
A31: =HYPERLINK('Link Config'!$B$2&"plugins/vc/alludium/documents/deal-room/ic-memo-review-template.md","IC Memo Review Template") | B31: template | C31: vc_deal_room | D31: Reusable review format for checking IC memo readiness, gaps, and required changes. | E31: review-ic-memo
A32: =HYPERLINK('Link Config'!$B$2&"plugins/vc/alludium/documents/deal-room/deal-terms-analysis-template.md","Deal Terms Analysis Template") | B32: template | C32: vc_deal_room | D32: Reusable commercial review format for valuation, ownership, dilution, ESOP, and round construction analysis. | E32: analyze-deal-terms
A33: =HYPERLINK('Link Config'!$B$2&"plugins/vc/alludium/documents/deal-room/term-sheet-negotiation-brief-template.md","Term Sheet Negotiation Brief Template") | B33: template | C33: vc_deal_room | D33: Reusable internal brief for open terms, give/get options, counsel questions, and approval points. | E33: track-term-sheet-negotiation
A34: =HYPERLINK('Link Config'!$B$2&"plugins/vc/alludium/documents/deal-room/term-sheet-review-template.md","Term Sheet Review Template") | B34: template | C34: vc_deal_room | D34: Reusable business review format for term-sheet deviations, red flags, and counsel questions. | E34: review-term-sheet
A35: =HYPERLINK('Link Config'!$B$2&"plugins/vc/alludium/documents/deal-room/legal-diligence-tracker-template.md","Legal Diligence Tracker Template") | B35: template | C35: vc_investment_management | D35: Reusable tracker for legal document indexing, issue registers, counsel questions, and showstopper-risk review support. | E35: run-legal-diligence
A36: =HYPERLINK('Link Config'!$B$2&"plugins/vc/alludium/documents/deal-room/legal-diligence-guide.md","Legal Diligence Guide") | B36: methodology | C36: vc_investment_management | D36: Legal diligence guidance for document indexing, issue tracking, counsel questions, and legal-risk escalation without legal advice. | E36: run-legal-diligence review-investment-documents manage-closing-checklist verify-conditions-precedent
A37: =HYPERLINK('Link Config'!$B$2&"plugins/vc/alludium/documents/deal-room/investment-document-review-template.md","Investment Document Review Template") | B37: template | C37: vc_investment_management | D37: Reusable review-support format for mapping investment documents back to approved terms and open counsel issues. | E37: review-investment-documents
A38: =HYPERLINK('Link Config'!$B$2&"plugins/vc/alludium/documents/deal-room/closing-checklist.md","Closing Checklist") | B38: checklist | C38: vc_investment_management | D38: Checklist for legal, finance, operational, and onboarding readiness before signing and completion. | E38: manage-closing-checklist
A39: =HYPERLINK('Link Config'!$B$2&"plugins/vc/alludium/documents/deal-room/conditions-precedent-tracker-template.md","Conditions Precedent Tracker Template") | B39: template | C39: vc_investment_management | D39: Reusable tracker for condition, owner, evidence, blocker, counsel review, and completion status. | E39: verify-conditions-precedent
A40: =HYPERLINK('Link Config'!$B$2&"plugins/vc/alludium/documents/deal-room/completion-tracker-template.md","Completion Tracker Template") | B40: template | C40: vc_investment_management | D40: Reusable tracker for capital call status, funds transfer readiness, completion evidence, and portfolio handoff triggers. | E40: coordinate-capital-call-and-completion
...

Sheet Task Skill Links
A1: Project | B1: Stage | C1: Task | D1: Skill
A2: Project Type | B2: Stage / Pseudo-stage | C2: Linked task | D2: Linked skill
A3: Deal Pipeline | B3: Setup | C3: =HYPERLINK('Link Config'!$B$2&"plugins/vc/tasks/screen-inbound-opportunity.md","Capture Opportunity Intake") | D3: =HYPERLINK('Link Config'!$B$2&"plugins/vc/skills/deal-room-setup-and-source-ingestion/SKILL.md","Deal Pipeline Setup & Source Ingestion")
A4: Deal Pipeline | B4: Setup | C4: =HYPERLINK('Link Config'!$B$2&"plugins/vc/tasks/screen-inbound-opportunity.md","Capture Opportunity Intake") | D4: =HYPERLINK('Link Config'!$B$2&"plugins/vc/skills/company-research-and-enrichment/SKILL.md","Company Research & Enrichment")
A5: Deal Pipeline | B5: Setup | C5: =HYPERLINK('Link Config'!$B$2&"plugins/vc/tasks/screen-inbound-opportunity.md","Capture Opportunity Intake") | D5: =HYPERLINK('Link Config'!$B$2&"plugins/vc/skills/citation-enforcement/SKILL.md","Citation Enforcement")
A6: Deal Pipeline | B6: Setup | C6: =HYPERLINK('Link Config'!$B$2&"plugins/vc/tasks/screen-inbound-opportunity.md","Capture Opportunity Intake") | D6: =HYPERLINK('Link Config'!$B$2&"plugins/vc/skills/pitch-deck-explainer/SKILL.md","Pitch Deck Explainer")
A7: Deal Pipeline | B7: Setup | C7: =HYPERLINK('Link Config'!$B$2&"plugins/vc/tasks/affinity-setup.md","Set Up Affinity for Deal Pipelines") | D7: =HYPERLINK('Link Config'!$B$2&"plugins/vc/skills/vc-affinity-discovery/SKILL.md","VC Affinity Discovery")
A8: Deal Pipeline | B8: Setup | C8: =HYPERLINK('Link Config'!$B$2&"plugins/vc/tasks/affinity-setup.md","Set Up Affinity for Deal Pipelines") | D8: =HYPERLINK('Link Config'!$B$2&"plugins/vc/skills/vc-affinity-sync-read/SKILL.md","VC Affinity Sync Read")
A9: Deal Pipeline | B9: Setup | C9: =HYPERLINK('Link Config'!$B$2&"plugins/vc/tasks/affinity-setup.md","Set Up Affinity for Deal Pipelines") | D9: =HYPERLINK('Link Config'!$B$2&"plugins/vc/skills/vc-affinity-sync-write/SKILL.md","VC Affinity Sync Write")
A10: Deal Pipeline | B10: Setup | C10: =HYPERLINK('Link Config'!$B$2&"plugins/vc/tasks/affinity-setup.md","Set Up Affinity for Deal Pipelines") | D10: =HYPERLINK('Link Config'!$B$2&"plugins/vc/skills/citation-enforcement/SKILL.md","Citation Enforcement")
A11: Deal Pipeline | B11: Setup | C11: =HYPERLINK('Link Config'!$B$2&"plugins/vc/tasks/affinity-deal-room-import.md","Import Affinity Deal Pipeline Seed") | D11: =HYPERLINK('Link Config'!$B$2&"plugins/vc/skills/vc-affinity-deal-room-import/SKILL.md","VC Affinity Deal Pipeline Import")
A12: Deal Pipeline | B12: Setup | C12: =HYPERLINK('Link Config'!$B$2&"plugins/vc/tasks/affinity-deal-room-import.md","Import Affinity Deal Pipeline Seed") | D12: =HYPERLINK('Link Config'!$B$2&"plugins/vc/skills/vc-affinity-sync-read/SKILL.md","VC Affinity Sync Read")
A13: Deal Pipeline | B13: Setup | C13: =HYPERLINK('Link Config'!$B$2&"plugins/vc/tasks/affinity-deal-room-import.md","Import Affinity Deal Pipeline Seed") | D13: =HYPERLINK('Link Config'!$B$2&"plugins/vc/skills/deal-room-setup-and-source-ingestion/SKILL.md","Deal Pipeline Setup & Source Ingestion")
A14: Deal Pipeline | B14: Setup | C14: =HYPERLINK('Link Config'!$B$2&"plugins/vc/tasks/affinity-deal-room-import.md","Import Affinity Deal Pipeline Seed") | D14: =HYPERLINK('Link Config'!$B$2&"plugins/vc/skills/citation-enforcement/SKILL.md","Citation Enforcement")
